<?xml version="1.0" encoding="UTF-8"?>
<testng-results skipped="0" failed="11" ignored="0" total="11" passed="0">
  <reporter-output>
  </reporter-output>
  <suite name="Default suite" duration-ms="12266" started-at="2020-03-10T05:14:44Z" finished-at="2020-03-10T05:14:56Z">
    <groups>
    </groups>
    <test name="Default test" duration-ms="12266" started-at="2020-03-10T05:14:44Z" finished-at="2020-03-10T05:14:56Z">
      <class name="com.tricentis.automation.libraries.TestingDataProviderAndXl">
        <test-method status="FAIL" signature="test1(java.lang.String, java.lang.String)[pri:0, instance:com.tricentis.automation.libraries.TestingDataProviderAndXl@475530b9]" name="test1" duration-ms="67" started-at="2020-03-10T10:44:56Z" data-provider="getData" finished-at="2020-03-10T10:44:56Z">
          <params>
            <param index="0">
              <value>
                <![CDATA[anand]]>
              </value>
            </param>
            <param index="1">
              <value>
                <![CDATA[password]]>
              </value>
            </param>
          </params>
          <exception class="java.lang.AssertionError">
            <message>
              <![CDATA[The following asserts failed:expected [asdsfgdf] but found [Anand],expected [asdsfgdf] but found [Anand1],expected [asdsfgdf] but found [Anand2],expected [asdsfgdf] but found [Anand3]]]>
            </message>
            <full-stacktrace>
              <![CDATA[java.lang.AssertionError: The following asserts failed:expected [asdsfgdf] but found [Anand],expected [asdsfgdf] but found [Anand1],expected [asdsfgdf] but found [Anand2],expected [asdsfgdf] but found [Anand3]at org.testng.asserts.SoftAssert.assertAll(SoftAssert.java:43)at com.tricentis.automation.libraries.TestingDataProviderAndXl.test1(TestingDataProviderAndXl.java:26)at sun.reflect.NativeMethodAccessorImpl.invoke0(Native Method)at sun.reflect.NativeMethodAccessorImpl.invoke(Unknown Source)at sun.reflect.DelegatingMethodAccessorImpl.invoke(Unknown Source)at java.lang.reflect.Method.invoke(Unknown Source)at org.testng.internal.MethodInvocationHelper.invokeMethod(MethodInvocationHelper.java:124)at org.testng.internal.Invoker.invokeMethod(Invoker.java:571)at org.testng.internal.Invoker.invokeTestMethod(Invoker.java:707)at org.testng.internal.Invoker.invokeTestMethods(Invoker.java:979)at org.testng.internal.TestMethodWorker.invokeTestMethods(TestMethodWorker.java:125)at org.testng.internal.TestMethodWorker.run(TestMethodWorker.java:109)at org.testng.TestRunner.privateRun(TestRunner.java:648)at org.testng.TestRunner.run(TestRunner.java:505)at org.testng.SuiteRunner.runTest(SuiteRunner.java:455)at org.testng.SuiteRunner.runSequentially(SuiteRunner.java:450)at org.testng.SuiteRunner.privateRun(SuiteRunner.java:415)at org.testng.SuiteRunner.run(SuiteRunner.java:364)at org.testng.SuiteRunnerWorker.runSuite(SuiteRunnerWorker.java:52)at org.testng.SuiteRunnerWorker.run(SuiteRunnerWorker.java:84)at org.testng.TestNG.runSuitesSequentially(TestNG.java:1187)at org.testng.TestNG.runSuitesLocally(TestNG.java:1116)at org.testng.TestNG.runSuites(TestNG.java:1028)at org.testng.TestNG.run(TestNG.java:996)at org.testng.remote.AbstractRemoteTestNG.run(AbstractRemoteTestNG.java:115)at org.testng.remote.RemoteTestNG.initAndRun(RemoteTestNG.java:251)at org.testng.remote.RemoteTestNG.main(RemoteTestNG.java:77)]]>
            </full-stacktrace>
          </exception> <!-- java.lang.AssertionError -->
          <reporter-output>
          </reporter-output>
        </test-method> <!-- test1 -->
        <test-method status="FAIL" signature="test1(java.lang.String, java.lang.String)[pri:0, instance:com.tricentis.automation.libraries.TestingDataProviderAndXl@475530b9]" name="test1" duration-ms="4" started-at="2020-03-10T10:44:56Z" data-provider="getData" finished-at="2020-03-10T10:44:56Z">
          <params>
            <param index="0">
              <value>
                <![CDATA[username1]]>
              </value>
            </param>
            <param index="1">
              <value>
                <![CDATA[password1]]>
              </value>
            </param>
          </params>
          <exception class="java.lang.AssertionError">
            <message>
              <![CDATA[The following asserts failed:expected [asdsfgdf] but found [Anand],expected [asdsfgdf] but found [Anand1],expected [asdsfgdf] but found [Anand2],expected [asdsfgdf] but found [Anand3]]]>
            </message>
            <full-stacktrace>
              <![CDATA[java.lang.AssertionError: The following asserts failed:expected [asdsfgdf] but found [Anand],expected [asdsfgdf] but found [Anand1],expected [asdsfgdf] but found [Anand2],expected [asdsfgdf] but found [Anand3]at org.testng.asserts.SoftAssert.assertAll(SoftAssert.java:43)at com.tricentis.automation.libraries.TestingDataProviderAndXl.test1(TestingDataProviderAndXl.java:26)at sun.reflect.NativeMethodAccessorImpl.invoke0(Native Method)at sun.reflect.NativeMethodAccessorImpl.invoke(Unknown Source)at sun.reflect.DelegatingMethodAccessorImpl.invoke(Unknown Source)at java.lang.reflect.Method.invoke(Unknown Source)at org.testng.internal.MethodInvocationHelper.invokeMethod(MethodInvocationHelper.java:124)at org.testng.internal.Invoker.invokeMethod(Invoker.java:571)at org.testng.internal.Invoker.invokeTestMethod(Invoker.java:707)at org.testng.internal.Invoker.invokeTestMethods(Invoker.java:979)at org.testng.internal.TestMethodWorker.invokeTestMethods(TestMethodWorker.java:125)at org.testng.internal.TestMethodWorker.run(TestMethodWorker.java:109)at org.testng.TestRunner.privateRun(TestRunner.java:648)at org.testng.TestRunner.run(TestRunner.java:505)at org.testng.SuiteRunner.runTest(SuiteRunner.java:455)at org.testng.SuiteRunner.runSequentially(SuiteRunner.java:450)at org.testng.SuiteRunner.privateRun(SuiteRunner.java:415)at org.testng.SuiteRunner.run(SuiteRunner.java:364)at org.testng.SuiteRunnerWorker.runSuite(SuiteRunnerWorker.java:52)at org.testng.SuiteRunnerWorker.run(SuiteRunnerWorker.java:84)at org.testng.TestNG.runSuitesSequentially(TestNG.java:1187)at org.testng.TestNG.runSuitesLocally(TestNG.java:1116)at org.testng.TestNG.runSuites(TestNG.java:1028)at org.testng.TestNG.run(TestNG.java:996)at org.testng.remote.AbstractRemoteTestNG.run(AbstractRemoteTestNG.java:115)at org.testng.remote.RemoteTestNG.initAndRun(RemoteTestNG.java:251)at org.testng.remote.RemoteTestNG.main(RemoteTestNG.java:77)]]>
            </full-stacktrace>
          </exception> <!-- java.lang.AssertionError -->
          <reporter-output>
          </reporter-output>
        </test-method> <!-- test1 -->
        <test-method status="FAIL" signature="test1(java.lang.String, java.lang.String)[pri:0, instance:com.tricentis.automation.libraries.TestingDataProviderAndXl@475530b9]" name="test1" duration-ms="4" started-at="2020-03-10T10:44:56Z" data-provider="getData" finished-at="2020-03-10T10:44:56Z">
          <params>
            <param index="0">
              <value>
                <![CDATA[username2]]>
              </value>
            </param>
            <param index="1">
              <value>
                <![CDATA[password2]]>
              </value>
            </param>
          </params>
          <exception class="java.lang.AssertionError">
            <message>
              <![CDATA[The following asserts failed:expected [asdsfgdf] but found [Anand],expected [asdsfgdf] but found [Anand1],expected [asdsfgdf] but found [Anand2],expected [asdsfgdf] but found [Anand3]]]>
            </message>
            <full-stacktrace>
              <![CDATA[java.lang.AssertionError: The following asserts failed:expected [asdsfgdf] but found [Anand],expected [asdsfgdf] but found [Anand1],expected [asdsfgdf] but found [Anand2],expected [asdsfgdf] but found [Anand3]at org.testng.asserts.SoftAssert.assertAll(SoftAssert.java:43)at com.tricentis.automation.libraries.TestingDataProviderAndXl.test1(TestingDataProviderAndXl.java:26)at sun.reflect.NativeMethodAccessorImpl.invoke0(Native Method)at sun.reflect.NativeMethodAccessorImpl.invoke(Unknown Source)at sun.reflect.DelegatingMethodAccessorImpl.invoke(Unknown Source)at java.lang.reflect.Method.invoke(Unknown Source)at org.testng.internal.MethodInvocationHelper.invokeMethod(MethodInvocationHelper.java:124)at org.testng.internal.Invoker.invokeMethod(Invoker.java:571)at org.testng.internal.Invoker.invokeTestMethod(Invoker.java:707)at org.testng.internal.Invoker.invokeTestMethods(Invoker.java:979)at org.testng.internal.TestMethodWorker.invokeTestMethods(TestMethodWorker.java:125)at org.testng.internal.TestMethodWorker.run(TestMethodWorker.java:109)at org.testng.TestRunner.privateRun(TestRunner.java:648)at org.testng.TestRunner.run(TestRunner.java:505)at org.testng.SuiteRunner.runTest(SuiteRunner.java:455)at org.testng.SuiteRunner.runSequentially(SuiteRunner.java:450)at org.testng.SuiteRunner.privateRun(SuiteRunner.java:415)at org.testng.SuiteRunner.run(SuiteRunner.java:364)at org.testng.SuiteRunnerWorker.runSuite(SuiteRunnerWorker.java:52)at org.testng.SuiteRunnerWorker.run(SuiteRunnerWorker.java:84)at org.testng.TestNG.runSuitesSequentially(TestNG.java:1187)at org.testng.TestNG.runSuitesLocally(TestNG.java:1116)at org.testng.TestNG.runSuites(TestNG.java:1028)at org.testng.TestNG.run(TestNG.java:996)at org.testng.remote.AbstractRemoteTestNG.run(AbstractRemoteTestNG.java:115)at org.testng.remote.RemoteTestNG.initAndRun(RemoteTestNG.java:251)at org.testng.remote.RemoteTestNG.main(RemoteTestNG.java:77)]]>
            </full-stacktrace>
          </exception> <!-- java.lang.AssertionError -->
          <reporter-output>
          </reporter-output>
        </test-method> <!-- test1 -->
        <test-method status="FAIL" signature="test1(java.lang.String, java.lang.String)[pri:0, instance:com.tricentis.automation.libraries.TestingDataProviderAndXl@475530b9]" name="test1" duration-ms="4" started-at="2020-03-10T10:44:56Z" data-provider="getData" finished-at="2020-03-10T10:44:56Z">
          <params>
            <param index="0">
              <value>
                <![CDATA[username3]]>
              </value>
            </param>
            <param index="1">
              <value>
                <![CDATA[password3]]>
              </value>
            </param>
          </params>
          <exception class="java.lang.AssertionError">
            <message>
              <![CDATA[The following asserts failed:expected [asdsfgdf] but found [Anand],expected [asdsfgdf] but found [Anand1],expected [asdsfgdf] but found [Anand2],expected [asdsfgdf] but found [Anand3]]]>
            </message>
            <full-stacktrace>
              <![CDATA[java.lang.AssertionError: The following asserts failed:expected [asdsfgdf] but found [Anand],expected [asdsfgdf] but found [Anand1],expected [asdsfgdf] but found [Anand2],expected [asdsfgdf] but found [Anand3]at org.testng.asserts.SoftAssert.assertAll(SoftAssert.java:43)at com.tricentis.automation.libraries.TestingDataProviderAndXl.test1(TestingDataProviderAndXl.java:26)at sun.reflect.NativeMethodAccessorImpl.invoke0(Native Method)at sun.reflect.NativeMethodAccessorImpl.invoke(Unknown Source)at sun.reflect.DelegatingMethodAccessorImpl.invoke(Unknown Source)at java.lang.reflect.Method.invoke(Unknown Source)at org.testng.internal.MethodInvocationHelper.invokeMethod(MethodInvocationHelper.java:124)at org.testng.internal.Invoker.invokeMethod(Invoker.java:571)at org.testng.internal.Invoker.invokeTestMethod(Invoker.java:707)at org.testng.internal.Invoker.invokeTestMethods(Invoker.java:979)at org.testng.internal.TestMethodWorker.invokeTestMethods(TestMethodWorker.java:125)at org.testng.internal.TestMethodWorker.run(TestMethodWorker.java:109)at org.testng.TestRunner.privateRun(TestRunner.java:648)at org.testng.TestRunner.run(TestRunner.java:505)at org.testng.SuiteRunner.runTest(SuiteRunner.java:455)at org.testng.SuiteRunner.runSequentially(SuiteRunner.java:450)at org.testng.SuiteRunner.privateRun(SuiteRunner.java:415)at org.testng.SuiteRunner.run(SuiteRunner.java:364)at org.testng.SuiteRunnerWorker.runSuite(SuiteRunnerWorker.java:52)at org.testng.SuiteRunnerWorker.run(SuiteRunnerWorker.java:84)at org.testng.TestNG.runSuitesSequentially(TestNG.java:1187)at org.testng.TestNG.runSuitesLocally(TestNG.java:1116)at org.testng.TestNG.runSuites(TestNG.java:1028)at org.testng.TestNG.run(TestNG.java:996)at org.testng.remote.AbstractRemoteTestNG.run(AbstractRemoteTestNG.java:115)at org.testng.remote.RemoteTestNG.initAndRun(RemoteTestNG.java:251)at org.testng.remote.RemoteTestNG.main(RemoteTestNG.java:77)]]>
            </full-stacktrace>
          </exception> <!-- java.lang.AssertionError -->
          <reporter-output>
          </reporter-output>
        </test-method> <!-- test1 -->
        <test-method status="FAIL" signature="test1(java.lang.String, java.lang.String)[pri:0, instance:com.tricentis.automation.libraries.TestingDataProviderAndXl@475530b9]" name="test1" duration-ms="8" started-at="2020-03-10T10:44:56Z" data-provider="getData" finished-at="2020-03-10T10:44:56Z">
          <params>
            <param index="0">
              <value>
                <![CDATA[username4]]>
              </value>
            </param>
            <param index="1">
              <value>
                <![CDATA[password4]]>
              </value>
            </param>
          </params>
          <exception class="java.lang.AssertionError">
            <message>
              <![CDATA[The following asserts failed:expected [asdsfgdf] but found [Anand],expected [asdsfgdf] but found [Anand1],expected [asdsfgdf] but found [Anand2],expected [asdsfgdf] but found [Anand3]]]>
            </message>
            <full-stacktrace>
              <![CDATA[java.lang.AssertionError: The following asserts failed:expected [asdsfgdf] but found [Anand],expected [asdsfgdf] but found [Anand1],expected [asdsfgdf] but found [Anand2],expected [asdsfgdf] but found [Anand3]at org.testng.asserts.SoftAssert.assertAll(SoftAssert.java:43)at com.tricentis.automation.libraries.TestingDataProviderAndXl.test1(TestingDataProviderAndXl.java:26)at sun.reflect.NativeMethodAccessorImpl.invoke0(Native Method)at sun.reflect.NativeMethodAccessorImpl.invoke(Unknown Source)at sun.reflect.DelegatingMethodAccessorImpl.invoke(Unknown Source)at java.lang.reflect.Method.invoke(Unknown Source)at org.testng.internal.MethodInvocationHelper.invokeMethod(MethodInvocationHelper.java:124)at org.testng.internal.Invoker.invokeMethod(Invoker.java:571)at org.testng.internal.Invoker.invokeTestMethod(Invoker.java:707)at org.testng.internal.Invoker.invokeTestMethods(Invoker.java:979)at org.testng.internal.TestMethodWorker.invokeTestMethods(TestMethodWorker.java:125)at org.testng.internal.TestMethodWorker.run(TestMethodWorker.java:109)at org.testng.TestRunner.privateRun(TestRunner.java:648)at org.testng.TestRunner.run(TestRunner.java:505)at org.testng.SuiteRunner.runTest(SuiteRunner.java:455)at org.testng.SuiteRunner.runSequentially(SuiteRunner.java:450)at org.testng.SuiteRunner.privateRun(SuiteRunner.java:415)at org.testng.SuiteRunner.run(SuiteRunner.java:364)at org.testng.SuiteRunnerWorker.runSuite(SuiteRunnerWorker.java:52)at org.testng.SuiteRunnerWorker.run(SuiteRunnerWorker.java:84)at org.testng.TestNG.runSuitesSequentially(TestNG.java:1187)at org.testng.TestNG.runSuitesLocally(TestNG.java:1116)at org.testng.TestNG.runSuites(TestNG.java:1028)at org.testng.TestNG.run(TestNG.java:996)at org.testng.remote.AbstractRemoteTestNG.run(AbstractRemoteTestNG.java:115)at org.testng.remote.RemoteTestNG.initAndRun(RemoteTestNG.java:251)at org.testng.remote.RemoteTestNG.main(RemoteTestNG.java:77)]]>
            </full-stacktrace>
          </exception> <!-- java.lang.AssertionError -->
          <reporter-output>
          </reporter-output>
        </test-method> <!-- test1 -->
        <test-method status="FAIL" signature="test1(java.lang.String, java.lang.String)[pri:0, instance:com.tricentis.automation.libraries.TestingDataProviderAndXl@475530b9]" name="test1" duration-ms="4" started-at="2020-03-10T10:44:56Z" data-provider="getData" finished-at="2020-03-10T10:44:56Z">
          <params>
            <param index="0">
              <value>
                <![CDATA[username5]]>
              </value>
            </param>
            <param index="1">
              <value>
                <![CDATA[password5]]>
              </value>
            </param>
          </params>
          <exception class="java.lang.AssertionError">
            <message>
              <![CDATA[The following asserts failed:expected [asdsfgdf] but found [Anand],expected [asdsfgdf] but found [Anand1],expected [asdsfgdf] but found [Anand2],expected [asdsfgdf] but found [Anand3]]]>
            </message>
            <full-stacktrace>
              <![CDATA[java.lang.AssertionError: The following asserts failed:expected [asdsfgdf] but found [Anand],expected [asdsfgdf] but found [Anand1],expected [asdsfgdf] but found [Anand2],expected [asdsfgdf] but found [Anand3]at org.testng.asserts.SoftAssert.assertAll(SoftAssert.java:43)at com.tricentis.automation.libraries.TestingDataProviderAndXl.test1(TestingDataProviderAndXl.java:26)at sun.reflect.NativeMethodAccessorImpl.invoke0(Native Method)at sun.reflect.NativeMethodAccessorImpl.invoke(Unknown Source)at sun.reflect.DelegatingMethodAccessorImpl.invoke(Unknown Source)at java.lang.reflect.Method.invoke(Unknown Source)at org.testng.internal.MethodInvocationHelper.invokeMethod(MethodInvocationHelper.java:124)at org.testng.internal.Invoker.invokeMethod(Invoker.java:571)at org.testng.internal.Invoker.invokeTestMethod(Invoker.java:707)at org.testng.internal.Invoker.invokeTestMethods(Invoker.java:979)at org.testng.internal.TestMethodWorker.invokeTestMethods(TestMethodWorker.java:125)at org.testng.internal.TestMethodWorker.run(TestMethodWorker.java:109)at org.testng.TestRunner.privateRun(TestRunner.java:648)at org.testng.TestRunner.run(TestRunner.java:505)at org.testng.SuiteRunner.runTest(SuiteRunner.java:455)at org.testng.SuiteRunner.runSequentially(SuiteRunner.java:450)at org.testng.SuiteRunner.privateRun(SuiteRunner.java:415)at org.testng.SuiteRunner.run(SuiteRunner.java:364)at org.testng.SuiteRunnerWorker.runSuite(SuiteRunnerWorker.java:52)at org.testng.SuiteRunnerWorker.run(SuiteRunnerWorker.java:84)at org.testng.TestNG.runSuitesSequentially(TestNG.java:1187)at org.testng.TestNG.runSuitesLocally(TestNG.java:1116)at org.testng.TestNG.runSuites(TestNG.java:1028)at org.testng.TestNG.run(TestNG.java:996)at org.testng.remote.AbstractRemoteTestNG.run(AbstractRemoteTestNG.java:115)at org.testng.remote.RemoteTestNG.initAndRun(RemoteTestNG.java:251)at org.testng.remote.RemoteTestNG.main(RemoteTestNG.java:77)]]>
            </full-stacktrace>
          </exception> <!-- java.lang.AssertionError -->
          <reporter-output>
          </reporter-output>
        </test-method> <!-- test1 -->
        <test-method status="FAIL" signature="test1(java.lang.String, java.lang.String)[pri:0, instance:com.tricentis.automation.libraries.TestingDataProviderAndXl@475530b9]" name="test1" duration-ms="4" started-at="2020-03-10T10:44:56Z" data-provider="getData" finished-at="2020-03-10T10:44:56Z">
          <params>
            <param index="0">
              <value>
                <![CDATA[username6]]>
              </value>
            </param>
            <param index="1">
              <value>
                <![CDATA[password6]]>
              </value>
            </param>
          </params>
          <exception class="java.lang.AssertionError">
            <message>
              <![CDATA[The following asserts failed:expected [asdsfgdf] but found [Anand],expected [asdsfgdf] but found [Anand1],expected [asdsfgdf] but found [Anand2],expected [asdsfgdf] but found [Anand3]]]>
            </message>
            <full-stacktrace>
              <![CDATA[java.lang.AssertionError: The following asserts failed:expected [asdsfgdf] but found [Anand],expected [asdsfgdf] but found [Anand1],expected [asdsfgdf] but found [Anand2],expected [asdsfgdf] but found [Anand3]at org.testng.asserts.SoftAssert.assertAll(SoftAssert.java:43)at com.tricentis.automation.libraries.TestingDataProviderAndXl.test1(TestingDataProviderAndXl.java:26)at sun.reflect.NativeMethodAccessorImpl.invoke0(Native Method)at sun.reflect.NativeMethodAccessorImpl.invoke(Unknown Source)at sun.reflect.DelegatingMethodAccessorImpl.invoke(Unknown Source)at java.lang.reflect.Method.invoke(Unknown Source)at org.testng.internal.MethodInvocationHelper.invokeMethod(MethodInvocationHelper.java:124)at org.testng.internal.Invoker.invokeMethod(Invoker.java:571)at org.testng.internal.Invoker.invokeTestMethod(Invoker.java:707)at org.testng.internal.Invoker.invokeTestMethods(Invoker.java:979)at org.testng.internal.TestMethodWorker.invokeTestMethods(TestMethodWorker.java:125)at org.testng.internal.TestMethodWorker.run(TestMethodWorker.java:109)at org.testng.TestRunner.privateRun(TestRunner.java:648)at org.testng.TestRunner.run(TestRunner.java:505)at org.testng.SuiteRunner.runTest(SuiteRunner.java:455)at org.testng.SuiteRunner.runSequentially(SuiteRunner.java:450)at org.testng.SuiteRunner.privateRun(SuiteRunner.java:415)at org.testng.SuiteRunner.run(SuiteRunner.java:364)at org.testng.SuiteRunnerWorker.runSuite(SuiteRunnerWorker.java:52)at org.testng.SuiteRunnerWorker.run(SuiteRunnerWorker.java:84)at org.testng.TestNG.runSuitesSequentially(TestNG.java:1187)at org.testng.TestNG.runSuitesLocally(TestNG.java:1116)at org.testng.TestNG.runSuites(TestNG.java:1028)at org.testng.TestNG.run(TestNG.java:996)at org.testng.remote.AbstractRemoteTestNG.run(AbstractRemoteTestNG.java:115)at org.testng.remote.RemoteTestNG.initAndRun(RemoteTestNG.java:251)at org.testng.remote.RemoteTestNG.main(RemoteTestNG.java:77)]]>
            </full-stacktrace>
          </exception> <!-- java.lang.AssertionError -->
          <reporter-output>
          </reporter-output>
        </test-method> <!-- test1 -->
        <test-method status="FAIL" signature="test1(java.lang.String, java.lang.String)[pri:0, instance:com.tricentis.automation.libraries.TestingDataProviderAndXl@475530b9]" name="test1" duration-ms="0" started-at="2020-03-10T10:44:56Z" data-provider="getData" finished-at="2020-03-10T10:44:56Z">
          <params>
            <param index="0">
              <value>
                <![CDATA[username7]]>
              </value>
            </param>
            <param index="1">
              <value>
                <![CDATA[password7]]>
              </value>
            </param>
          </params>
          <exception class="java.lang.AssertionError">
            <message>
              <![CDATA[The following asserts failed:expected [asdsfgdf] but found [Anand],expected [asdsfgdf] but found [Anand1],expected [asdsfgdf] but found [Anand2],expected [asdsfgdf] but found [Anand3]]]>
            </message>
            <full-stacktrace>
              <![CDATA[java.lang.AssertionError: The following asserts failed:expected [asdsfgdf] but found [Anand],expected [asdsfgdf] but found [Anand1],expected [asdsfgdf] but found [Anand2],expected [asdsfgdf] but found [Anand3]at org.testng.asserts.SoftAssert.assertAll(SoftAssert.java:43)at com.tricentis.automation.libraries.TestingDataProviderAndXl.test1(TestingDataProviderAndXl.java:26)at sun.reflect.NativeMethodAccessorImpl.invoke0(Native Method)at sun.reflect.NativeMethodAccessorImpl.invoke(Unknown Source)at sun.reflect.DelegatingMethodAccessorImpl.invoke(Unknown Source)at java.lang.reflect.Method.invoke(Unknown Source)at org.testng.internal.MethodInvocationHelper.invokeMethod(MethodInvocationHelper.java:124)at org.testng.internal.Invoker.invokeMethod(Invoker.java:571)at org.testng.internal.Invoker.invokeTestMethod(Invoker.java:707)at org.testng.internal.Invoker.invokeTestMethods(Invoker.java:979)at org.testng.internal.TestMethodWorker.invokeTestMethods(TestMethodWorker.java:125)at org.testng.internal.TestMethodWorker.run(TestMethodWorker.java:109)at org.testng.TestRunner.privateRun(TestRunner.java:648)at org.testng.TestRunner.run(TestRunner.java:505)at org.testng.SuiteRunner.runTest(SuiteRunner.java:455)at org.testng.SuiteRunner.runSequentially(SuiteRunner.java:450)at org.testng.SuiteRunner.privateRun(SuiteRunner.java:415)at org.testng.SuiteRunner.run(SuiteRunner.java:364)at org.testng.SuiteRunnerWorker.runSuite(SuiteRunnerWorker.java:52)at org.testng.SuiteRunnerWorker.run(SuiteRunnerWorker.java:84)at org.testng.TestNG.runSuitesSequentially(TestNG.java:1187)at org.testng.TestNG.runSuitesLocally(TestNG.java:1116)at org.testng.TestNG.runSuites(TestNG.java:1028)at org.testng.TestNG.run(TestNG.java:996)at org.testng.remote.AbstractRemoteTestNG.run(AbstractRemoteTestNG.java:115)at org.testng.remote.RemoteTestNG.initAndRun(RemoteTestNG.java:251)at org.testng.remote.RemoteTestNG.main(RemoteTestNG.java:77)]]>
            </full-stacktrace>
          </exception> <!-- java.lang.AssertionError -->
          <reporter-output>
          </reporter-output>
        </test-method> <!-- test1 -->
        <test-method status="FAIL" signature="test1(java.lang.String, java.lang.String)[pri:0, instance:com.tricentis.automation.libraries.TestingDataProviderAndXl@475530b9]" name="test1" duration-ms="0" started-at="2020-03-10T10:44:56Z" data-provider="getData" finished-at="2020-03-10T10:44:56Z">
          <params>
            <param index="0">
              <value>
                <![CDATA[username8]]>
              </value>
            </param>
            <param index="1">
              <value>
                <![CDATA[password8]]>
              </value>
            </param>
          </params>
          <exception class="java.lang.AssertionError">
            <message>
              <![CDATA[The following asserts failed:expected [asdsfgdf] but found [Anand],expected [asdsfgdf] but found [Anand1],expected [asdsfgdf] but found [Anand2],expected [asdsfgdf] but found [Anand3]]]>
            </message>
            <full-stacktrace>
              <![CDATA[java.lang.AssertionError: The following asserts failed:expected [asdsfgdf] but found [Anand],expected [asdsfgdf] but found [Anand1],expected [asdsfgdf] but found [Anand2],expected [asdsfgdf] but found [Anand3]at org.testng.asserts.SoftAssert.assertAll(SoftAssert.java:43)at com.tricentis.automation.libraries.TestingDataProviderAndXl.test1(TestingDataProviderAndXl.java:26)at sun.reflect.NativeMethodAccessorImpl.invoke0(Native Method)at sun.reflect.NativeMethodAccessorImpl.invoke(Unknown Source)at sun.reflect.DelegatingMethodAccessorImpl.invoke(Unknown Source)at java.lang.reflect.Method.invoke(Unknown Source)at org.testng.internal.MethodInvocationHelper.invokeMethod(MethodInvocationHelper.java:124)at org.testng.internal.Invoker.invokeMethod(Invoker.java:571)at org.testng.internal.Invoker.invokeTestMethod(Invoker.java:707)at org.testng.internal.Invoker.invokeTestMethods(Invoker.java:979)at org.testng.internal.TestMethodWorker.invokeTestMethods(TestMethodWorker.java:125)at org.testng.internal.TestMethodWorker.run(TestMethodWorker.java:109)at org.testng.TestRunner.privateRun(TestRunner.java:648)at org.testng.TestRunner.run(TestRunner.java:505)at org.testng.SuiteRunner.runTest(SuiteRunner.java:455)at org.testng.SuiteRunner.runSequentially(SuiteRunner.java:450)at org.testng.SuiteRunner.privateRun(SuiteRunner.java:415)at org.testng.SuiteRunner.run(SuiteRunner.java:364)at org.testng.SuiteRunnerWorker.runSuite(SuiteRunnerWorker.java:52)at org.testng.SuiteRunnerWorker.run(SuiteRunnerWorker.java:84)at org.testng.TestNG.runSuitesSequentially(TestNG.java:1187)at org.testng.TestNG.runSuitesLocally(TestNG.java:1116)at org.testng.TestNG.runSuites(TestNG.java:1028)at org.testng.TestNG.run(TestNG.java:996)at org.testng.remote.AbstractRemoteTestNG.run(AbstractRemoteTestNG.java:115)at org.testng.remote.RemoteTestNG.initAndRun(RemoteTestNG.java:251)at org.testng.remote.RemoteTestNG.main(RemoteTestNG.java:77)]]>
            </full-stacktrace>
          </exception> <!-- java.lang.AssertionError -->
          <reporter-output>
          </reporter-output>
        </test-method> <!-- test1 -->
        <test-method status="FAIL" signature="test1(java.lang.String, java.lang.String)[pri:0, instance:com.tricentis.automation.libraries.TestingDataProviderAndXl@475530b9]" name="test1" duration-ms="12" started-at="2020-03-10T10:44:56Z" data-provider="getData" finished-at="2020-03-10T10:44:56Z">
          <params>
            <param index="0">
              <value>
                <![CDATA[username9]]>
              </value>
            </param>
            <param index="1">
              <value>
                <![CDATA[password9]]>
              </value>
            </param>
          </params>
          <exception class="java.lang.AssertionError">
            <message>
              <![CDATA[The following asserts failed:expected [asdsfgdf] but found [Anand],expected [asdsfgdf] but found [Anand1],expected [asdsfgdf] but found [Anand2],expected [asdsfgdf] but found [Anand3]]]>
            </message>
            <full-stacktrace>
              <![CDATA[java.lang.AssertionError: The following asserts failed:expected [asdsfgdf] but found [Anand],expected [asdsfgdf] but found [Anand1],expected [asdsfgdf] but found [Anand2],expected [asdsfgdf] but found [Anand3]at org.testng.asserts.SoftAssert.assertAll(SoftAssert.java:43)at com.tricentis.automation.libraries.TestingDataProviderAndXl.test1(TestingDataProviderAndXl.java:26)at sun.reflect.NativeMethodAccessorImpl.invoke0(Native Method)at sun.reflect.NativeMethodAccessorImpl.invoke(Unknown Source)at sun.reflect.DelegatingMethodAccessorImpl.invoke(Unknown Source)at java.lang.reflect.Method.invoke(Unknown Source)at org.testng.internal.MethodInvocationHelper.invokeMethod(MethodInvocationHelper.java:124)at org.testng.internal.Invoker.invokeMethod(Invoker.java:571)at org.testng.internal.Invoker.invokeTestMethod(Invoker.java:707)at org.testng.internal.Invoker.invokeTestMethods(Invoker.java:979)at org.testng.internal.TestMethodWorker.invokeTestMethods(TestMethodWorker.java:125)at org.testng.internal.TestMethodWorker.run(TestMethodWorker.java:109)at org.testng.TestRunner.privateRun(TestRunner.java:648)at org.testng.TestRunner.run(TestRunner.java:505)at org.testng.SuiteRunner.runTest(SuiteRunner.java:455)at org.testng.SuiteRunner.runSequentially(SuiteRunner.java:450)at org.testng.SuiteRunner.privateRun(SuiteRunner.java:415)at org.testng.SuiteRunner.run(SuiteRunner.java:364)at org.testng.SuiteRunnerWorker.runSuite(SuiteRunnerWorker.java:52)at org.testng.SuiteRunnerWorker.run(SuiteRunnerWorker.java:84)at org.testng.TestNG.runSuitesSequentially(TestNG.java:1187)at org.testng.TestNG.runSuitesLocally(TestNG.java:1116)at org.testng.TestNG.runSuites(TestNG.java:1028)at org.testng.TestNG.run(TestNG.java:996)at org.testng.remote.AbstractRemoteTestNG.run(AbstractRemoteTestNG.java:115)at org.testng.remote.RemoteTestNG.initAndRun(RemoteTestNG.java:251)at org.testng.remote.RemoteTestNG.main(RemoteTestNG.java:77)]]>
            </full-stacktrace>
          </exception> <!-- java.lang.AssertionError -->
          <reporter-output>
          </reporter-output>
        </test-method> <!-- test1 -->
        <test-method status="FAIL" signature="test1(java.lang.String, java.lang.String)[pri:0, instance:com.tricentis.automation.libraries.TestingDataProviderAndXl@475530b9]" name="test1" duration-ms="12" started-at="2020-03-10T10:44:56Z" data-provider="getData" finished-at="2020-03-10T10:44:56Z">
          <params>
            <param index="0">
              <value>
                <![CDATA[username10]]>
              </value>
            </param>
            <param index="1">
              <value>
                <![CDATA[password10]]>
              </value>
            </param>
          </params>
          <exception class="java.lang.AssertionError">
            <message>
              <![CDATA[The following asserts failed:expected [asdsfgdf] but found [Anand],expected [asdsfgdf] but found [Anand1],expected [asdsfgdf] but found [Anand2],expected [asdsfgdf] but found [Anand3]]]>
            </message>
            <full-stacktrace>
              <![CDATA[java.lang.AssertionError: The following asserts failed:expected [asdsfgdf] but found [Anand],expected [asdsfgdf] but found [Anand1],expected [asdsfgdf] but found [Anand2],expected [asdsfgdf] but found [Anand3]at org.testng.asserts.SoftAssert.assertAll(SoftAssert.java:43)at com.tricentis.automation.libraries.TestingDataProviderAndXl.test1(TestingDataProviderAndXl.java:26)at sun.reflect.NativeMethodAccessorImpl.invoke0(Native Method)at sun.reflect.NativeMethodAccessorImpl.invoke(Unknown Source)at sun.reflect.DelegatingMethodAccessorImpl.invoke(Unknown Source)at java.lang.reflect.Method.invoke(Unknown Source)at org.testng.internal.MethodInvocationHelper.invokeMethod(MethodInvocationHelper.java:124)at org.testng.internal.Invoker.invokeMethod(Invoker.java:571)at org.testng.internal.Invoker.invokeTestMethod(Invoker.java:707)at org.testng.internal.Invoker.invokeTestMethods(Invoker.java:979)at org.testng.internal.TestMethodWorker.invokeTestMethods(TestMethodWorker.java:125)at org.testng.internal.TestMethodWorker.run(TestMethodWorker.java:109)at org.testng.TestRunner.privateRun(TestRunner.java:648)at org.testng.TestRunner.run(TestRunner.java:505)at org.testng.SuiteRunner.runTest(SuiteRunner.java:455)at org.testng.SuiteRunner.runSequentially(SuiteRunner.java:450)at org.testng.SuiteRunner.privateRun(SuiteRunner.java:415)at org.testng.SuiteRunner.run(SuiteRunner.java:364)at org.testng.SuiteRunnerWorker.runSuite(SuiteRunnerWorker.java:52)at org.testng.SuiteRunnerWorker.run(SuiteRunnerWorker.java:84)at org.testng.TestNG.runSuitesSequentially(TestNG.java:1187)at org.testng.TestNG.runSuitesLocally(TestNG.java:1116)at org.testng.TestNG.runSuites(TestNG.java:1028)at org.testng.TestNG.run(TestNG.java:996)at org.testng.remote.AbstractRemoteTestNG.run(AbstractRemoteTestNG.java:115)at org.testng.remote.RemoteTestNG.initAndRun(RemoteTestNG.java:251)at org.testng.remote.RemoteTestNG.main(RemoteTestNG.java:77)]]>
            </full-stacktrace>
          </exception> <!-- java.lang.AssertionError -->
          <reporter-output>
          </reporter-output>
        </test-method> <!-- test1 -->
      </class> <!-- com.tricentis.automation.libraries.TestingDataProviderAndXl -->
    </test> <!-- Default test -->
  </suite> <!-- Default suite -->
</testng-results>
